Watching for file changes with StatReloader
"GET / HTTP/1.1" 200 3168
"GET /api/activitytracker/dashboard/ HTTP/1.1" 200 13805
"GET /api/activitytracker/dashboard/ HTTP/1.1" 200 13805
"GET /static/activitytracker/images/trackerlogo.jpg HTTP/1.1" 200 196085
"GET /static/activitytracker/images/backgroundimage.jpg HTTP/1.1" 200 6235780
"GET /static/activitytracker/images/favicon.ico HTTP/1.1" 200 15406
Internal Server Error: /api/activitytracker/record/
Traceback (most recent call last):
  File "/usr/local/python/3.12.1/lib/python3.12/site-packages/django/core/handlers/exception.py", line 55, in inner
    response = get_response(request)
               ^^^^^^^^^^^^^^^^^^^^^
  File "/usr/local/python/3.12.1/lib/python3.12/site-packages/django/core/handlers/base.py", line 197, in _get_response
    response = wrapped_callback(request, *callback_args, **callback_kwargs)
               ^^^^^^^^^^^^^^^^^^^^^^^^^^^^^^^^^^^^^^^^^^^^^^^^^^^^^^^^^^^^
  File "/usr/local/python/3.12.1/lib/python3.12/site-packages/django/contrib/auth/decorators.py", line 23, in _wrapper_view
    return view_func(request, *args, **kwargs)
           ^^^^^^^^^^^^^^^^^^^^^^^^^^^^^^^^^^^
  File "/workspaces/activitytracker/activitytracker/views.py", line 155, in record_activity
    activity.save()
  File "/usr/local/python/3.12.1/lib/python3.12/site-packages/django/db/models/base.py", line 822, in save
    self.save_base(
  File "/usr/local/python/3.12.1/lib/python3.12/site-packages/django/db/models/base.py", line 909, in save_base
    updated = self._save_table(
              ^^^^^^^^^^^^^^^^^
  File "/usr/local/python/3.12.1/lib/python3.12/site-packages/django/db/models/base.py", line 1067, in _save_table
    results = self._do_insert(
              ^^^^^^^^^^^^^^^^
  File "/usr/local/python/3.12.1/lib/python3.12/site-packages/django/db/models/base.py", line 1108, in _do_insert
    return manager._insert(
           ^^^^^^^^^^^^^^^^
  File "/usr/local/python/3.12.1/lib/python3.12/site-packages/django/db/models/manager.py", line 87, in manager_method
    return getattr(self.get_queryset(), name)(*args, **kwargs)
           ^^^^^^^^^^^^^^^^^^^^^^^^^^^^^^^^^^^^^^^^^^^^^^^^^^^
  File "/usr/local/python/3.12.1/lib/python3.12/site-packages/django/db/models/query.py", line 1847, in _insert
    return query.get_compiler(using=using).execute_sql(returning_fields)
           ^^^^^^^^^^^^^^^^^^^^^^^^^^^^^^^^^^^^^^^^^^^^^^^^^^^^^^^^^^^^^
  File "/usr/local/python/3.12.1/lib/python3.12/site-packages/django/db/models/sql/compiler.py", line 1822, in execute_sql
    for sql, params in self.as_sql():
                       ^^^^^^^^^^^^^
  File "/usr/local/python/3.12.1/lib/python3.12/site-packages/django/db/models/sql/compiler.py", line 1747, in as_sql
    self.prepare_value(field, self.pre_save_val(field, obj))
                              ^^^^^^^^^^^^^^^^^^^^^^^^^^^^^
  File "/usr/local/python/3.12.1/lib/python3.12/site-packages/django/db/models/sql/compiler.py", line 1695, in pre_save_val
    return field.pre_save(obj, add=True)
           ^^^^^^^^^^^^^^^^^^^^^^^^^^^^^
  File "/usr/local/python/3.12.1/lib/python3.12/site-packages/django/db/models/fields/files.py", line 317, in pre_save
    file.save(file.name, file.file, save=False)
  File "/usr/local/python/3.12.1/lib/python3.12/site-packages/django/db/models/fields/files.py", line 93, in save
    self.name = self.storage.save(name, content, max_length=self.field.max_length)
                ^^^^^^^^^^^^^^^^^^^^^^^^^^^^^^^^^^^^^^^^^^^^^^^^^^^^^^^^^^^^^^^^^^
  File "/usr/local/python/3.12.1/lib/python3.12/site-packages/django/core/files/storage/base.py", line 38, in save
    name = self._save(name, content)
           ^^^^^^^^^^^^^^^^^^^^^^^^^
  File "/usr/local/python/3.12.1/lib/python3.12/site-packages/cloudinary_storage/storage.py", line 68, in _save
    response = self._upload(name, content)
               ^^^^^^^^^^^^^^^^^^^^^^^^^^^
  File "/usr/local/python/3.12.1/lib/python3.12/site-packages/cloudinary_storage/storage.py", line 62, in _upload
    return cloudinary.uploader.upload(content, **options)
           ^^^^^^^^^^^^^^^^^^^^^^^^^^^^^^^^^^^^^^^^^^^^^^
  File "/usr/local/python/3.12.1/lib/python3.12/site-packages/cloudinary/uploader.py", line 197, in upload
    return call_cacheable_api("upload", params, file=file, **options)
           ^^^^^^^^^^^^^^^^^^^^^^^^^^^^^^^^^^^^^^^^^^^^^^^^^^^^^^^^^^
  File "/usr/local/python/3.12.1/lib/python3.12/site-packages/cloudinary/uploader.py", line 833, in call_cacheable_api
    result = call_api(action, params, http_headers, return_error, unsigned, file, timeout, **options)
             ^^^^^^^^^^^^^^^^^^^^^^^^^^^^^^^^^^^^^^^^^^^^^^^^^^^^^^^^^^^^^^^^^^^^^^^^^^^^^^^^^^^^^^^^
  File "/usr/local/python/3.12.1/lib/python3.12/site-packages/cloudinary/uploader.py", line 921, in call_api
    raise Error(result["error"]["message"])
cloudinary.exceptions.Error: Empty file
"POST /api/activitytracker/record/ HTTP/1.1" 500 183602
Not Found: /favicon.ico
"GET /favicon.ico HTTP/1.1" 404 3348
/workspaces/activitytracker/activitytracker/views.py changed, reloading.
Watching for file changes with StatReloader
Watching for file changes with StatReloader
"GET / HTTP/1.1" 200 3168
"GET /api/activitytracker/dashboard/ HTTP/1.1" 200 13805
Internal Server Error: /api/activitytracker/record/
Traceback (most recent call last):
  File "/usr/local/python/3.12.1/lib/python3.12/site-packages/django/core/handlers/exception.py", line 55, in inner
    response = get_response(request)
               ^^^^^^^^^^^^^^^^^^^^^
  File "/usr/local/python/3.12.1/lib/python3.12/site-packages/django/core/handlers/base.py", line 197, in _get_response
    response = wrapped_callback(request, *callback_args, **callback_kwargs)
               ^^^^^^^^^^^^^^^^^^^^^^^^^^^^^^^^^^^^^^^^^^^^^^^^^^^^^^^^^^^^
  File "/usr/local/python/3.12.1/lib/python3.12/site-packages/django/contrib/auth/decorators.py", line 23, in _wrapper_view
    return view_func(request, *args, **kwargs)
           ^^^^^^^^^^^^^^^^^^^^^^^^^^^^^^^^^^^
  File "/workspaces/activitytracker/activitytracker/views.py", line 149, in record_activity
    activity.save()
  File "/usr/local/python/3.12.1/lib/python3.12/site-packages/django/db/models/base.py", line 822, in save
    self.save_base(
  File "/usr/local/python/3.12.1/lib/python3.12/site-packages/django/db/models/base.py", line 909, in save_base
    updated = self._save_table(
              ^^^^^^^^^^^^^^^^^
  File "/usr/local/python/3.12.1/lib/python3.12/site-packages/django/db/models/base.py", line 1067, in _save_table
    results = self._do_insert(
              ^^^^^^^^^^^^^^^^
  File "/usr/local/python/3.12.1/lib/python3.12/site-packages/django/db/models/base.py", line 1108, in _do_insert
    return manager._insert(
           ^^^^^^^^^^^^^^^^
  File "/usr/local/python/3.12.1/lib/python3.12/site-packages/django/db/models/manager.py", line 87, in manager_method
    return getattr(self.get_queryset(), name)(*args, **kwargs)
           ^^^^^^^^^^^^^^^^^^^^^^^^^^^^^^^^^^^^^^^^^^^^^^^^^^^
  File "/usr/local/python/3.12.1/lib/python3.12/site-packages/django/db/models/query.py", line 1847, in _insert
    return query.get_compiler(using=using).execute_sql(returning_fields)
           ^^^^^^^^^^^^^^^^^^^^^^^^^^^^^^^^^^^^^^^^^^^^^^^^^^^^^^^^^^^^^
  File "/usr/local/python/3.12.1/lib/python3.12/site-packages/django/db/models/sql/compiler.py", line 1822, in execute_sql
    for sql, params in self.as_sql():
                       ^^^^^^^^^^^^^
  File "/usr/local/python/3.12.1/lib/python3.12/site-packages/django/db/models/sql/compiler.py", line 1747, in as_sql
    self.prepare_value(field, self.pre_save_val(field, obj))
                              ^^^^^^^^^^^^^^^^^^^^^^^^^^^^^
  File "/usr/local/python/3.12.1/lib/python3.12/site-packages/django/db/models/sql/compiler.py", line 1695, in pre_save_val
    return field.pre_save(obj, add=True)
           ^^^^^^^^^^^^^^^^^^^^^^^^^^^^^
  File "/usr/local/python/3.12.1/lib/python3.12/site-packages/django/db/models/fields/files.py", line 317, in pre_save
    file.save(file.name, file.file, save=False)
  File "/usr/local/python/3.12.1/lib/python3.12/site-packages/django/db/models/fields/files.py", line 93, in save
    self.name = self.storage.save(name, content, max_length=self.field.max_length)
                ^^^^^^^^^^^^^^^^^^^^^^^^^^^^^^^^^^^^^^^^^^^^^^^^^^^^^^^^^^^^^^^^^^
  File "/usr/local/python/3.12.1/lib/python3.12/site-packages/django/core/files/storage/base.py", line 38, in save
    name = self._save(name, content)
           ^^^^^^^^^^^^^^^^^^^^^^^^^
  File "/usr/local/python/3.12.1/lib/python3.12/site-packages/cloudinary_storage/storage.py", line 68, in _save
    response = self._upload(name, content)
               ^^^^^^^^^^^^^^^^^^^^^^^^^^^
  File "/usr/local/python/3.12.1/lib/python3.12/site-packages/cloudinary_storage/storage.py", line 62, in _upload
    return cloudinary.uploader.upload(content, **options)
           ^^^^^^^^^^^^^^^^^^^^^^^^^^^^^^^^^^^^^^^^^^^^^^
  File "/usr/local/python/3.12.1/lib/python3.12/site-packages/cloudinary/uploader.py", line 197, in upload
    return call_cacheable_api("upload", params, file=file, **options)
           ^^^^^^^^^^^^^^^^^^^^^^^^^^^^^^^^^^^^^^^^^^^^^^^^^^^^^^^^^^
  File "/usr/local/python/3.12.1/lib/python3.12/site-packages/cloudinary/uploader.py", line 833, in call_cacheable_api
    result = call_api(action, params, http_headers, return_error, unsigned, file, timeout, **options)
             ^^^^^^^^^^^^^^^^^^^^^^^^^^^^^^^^^^^^^^^^^^^^^^^^^^^^^^^^^^^^^^^^^^^^^^^^^^^^^^^^^^^^^^^^
  File "/usr/local/python/3.12.1/lib/python3.12/site-packages/cloudinary/uploader.py", line 921, in call_api
    raise Error(result["error"]["message"])
cloudinary.exceptions.Error: Empty file
"POST /api/activitytracker/record/ HTTP/1.1" 500 177543
Watching for file changes with StatReloader
/workspaces/activitytracker/activitytracker/views.py changed, reloading.
Watching for file changes with StatReloader
Watching for file changes with StatReloader
/workspaces/activitytracker/activitytracker/views.py changed, reloading.
/workspaces/activitytracker/activitytracker/views.py changed, reloading.
Watching for file changes with StatReloader
Watching for file changes with StatReloader
"GET / HTTP/1.1" 200 3168
"GET /api/activitytracker/dashboard/ HTTP/1.1" 200 13805
Internal Server Error: /api/activitytracker/record/
Traceback (most recent call last):
  File "/usr/local/python/3.12.1/lib/python3.12/site-packages/django/core/handlers/exception.py", line 55, in inner
    response = get_response(request)
               ^^^^^^^^^^^^^^^^^^^^^
  File "/usr/local/python/3.12.1/lib/python3.12/site-packages/django/core/handlers/base.py", line 197, in _get_response
    response = wrapped_callback(request, *callback_args, **callback_kwargs)
               ^^^^^^^^^^^^^^^^^^^^^^^^^^^^^^^^^^^^^^^^^^^^^^^^^^^^^^^^^^^^
  File "/usr/local/python/3.12.1/lib/python3.12/site-packages/django/contrib/auth/decorators.py", line 23, in _wrapper_view
    return view_func(request, *args, **kwargs)
           ^^^^^^^^^^^^^^^^^^^^^^^^^^^^^^^^^^^
  File "/workspaces/activitytracker/activitytracker/views.py", line 152, in record_activity
    activity.save()
  File "/usr/local/python/3.12.1/lib/python3.12/site-packages/django/db/models/base.py", line 822, in save
    self.save_base(
  File "/usr/local/python/3.12.1/lib/python3.12/site-packages/django/db/models/base.py", line 909, in save_base
    updated = self._save_table(
              ^^^^^^^^^^^^^^^^^
  File "/usr/local/python/3.12.1/lib/python3.12/site-packages/django/db/models/base.py", line 1067, in _save_table
    results = self._do_insert(
              ^^^^^^^^^^^^^^^^
  File "/usr/local/python/3.12.1/lib/python3.12/site-packages/django/db/models/base.py", line 1108, in _do_insert
    return manager._insert(
           ^^^^^^^^^^^^^^^^
  File "/usr/local/python/3.12.1/lib/python3.12/site-packages/django/db/models/manager.py", line 87, in manager_method
    return getattr(self.get_queryset(), name)(*args, **kwargs)
           ^^^^^^^^^^^^^^^^^^^^^^^^^^^^^^^^^^^^^^^^^^^^^^^^^^^
  File "/usr/local/python/3.12.1/lib/python3.12/site-packages/django/db/models/query.py", line 1847, in _insert
    return query.get_compiler(using=using).execute_sql(returning_fields)
           ^^^^^^^^^^^^^^^^^^^^^^^^^^^^^^^^^^^^^^^^^^^^^^^^^^^^^^^^^^^^^
  File "/usr/local/python/3.12.1/lib/python3.12/site-packages/django/db/models/sql/compiler.py", line 1822, in execute_sql
    for sql, params in self.as_sql():
                       ^^^^^^^^^^^^^
  File "/usr/local/python/3.12.1/lib/python3.12/site-packages/django/db/models/sql/compiler.py", line 1747, in as_sql
    self.prepare_value(field, self.pre_save_val(field, obj))
                              ^^^^^^^^^^^^^^^^^^^^^^^^^^^^^
  File "/usr/local/python/3.12.1/lib/python3.12/site-packages/django/db/models/sql/compiler.py", line 1695, in pre_save_val
    return field.pre_save(obj, add=True)
           ^^^^^^^^^^^^^^^^^^^^^^^^^^^^^
  File "/usr/local/python/3.12.1/lib/python3.12/site-packages/django/db/models/fields/files.py", line 317, in pre_save
    file.save(file.name, file.file, save=False)
  File "/usr/local/python/3.12.1/lib/python3.12/site-packages/django/db/models/fields/files.py", line 93, in save
    self.name = self.storage.save(name, content, max_length=self.field.max_length)
                ^^^^^^^^^^^^^^^^^^^^^^^^^^^^^^^^^^^^^^^^^^^^^^^^^^^^^^^^^^^^^^^^^^
  File "/usr/local/python/3.12.1/lib/python3.12/site-packages/django/core/files/storage/base.py", line 38, in save
    name = self._save(name, content)
           ^^^^^^^^^^^^^^^^^^^^^^^^^
  File "/usr/local/python/3.12.1/lib/python3.12/site-packages/cloudinary_storage/storage.py", line 68, in _save
    response = self._upload(name, content)
               ^^^^^^^^^^^^^^^^^^^^^^^^^^^
  File "/usr/local/python/3.12.1/lib/python3.12/site-packages/cloudinary_storage/storage.py", line 62, in _upload
    return cloudinary.uploader.upload(content, **options)
           ^^^^^^^^^^^^^^^^^^^^^^^^^^^^^^^^^^^^^^^^^^^^^^
  File "/usr/local/python/3.12.1/lib/python3.12/site-packages/cloudinary/uploader.py", line 197, in upload
    return call_cacheable_api("upload", params, file=file, **options)
           ^^^^^^^^^^^^^^^^^^^^^^^^^^^^^^^^^^^^^^^^^^^^^^^^^^^^^^^^^^
  File "/usr/local/python/3.12.1/lib/python3.12/site-packages/cloudinary/uploader.py", line 833, in call_cacheable_api
    result = call_api(action, params, http_headers, return_error, unsigned, file, timeout, **options)
             ^^^^^^^^^^^^^^^^^^^^^^^^^^^^^^^^^^^^^^^^^^^^^^^^^^^^^^^^^^^^^^^^^^^^^^^^^^^^^^^^^^^^^^^^
  File "/usr/local/python/3.12.1/lib/python3.12/site-packages/cloudinary/uploader.py", line 921, in call_api
    raise Error(result["error"]["message"])
cloudinary.exceptions.Error: Empty file
"POST /api/activitytracker/record/ HTTP/1.1" 500 177458
Not Found: /favicon.ico
"GET /favicon.ico HTTP/1.1" 404 3348
/workspaces/activitytracker/activitytracker/forms.py changed, reloading.
Watching for file changes with StatReloader
Internal Server Error: /api/activitytracker/record/
Traceback (most recent call last):
  File "/usr/local/python/3.12.1/lib/python3.12/site-packages/gpxpy/parser.py", line 134, in parse
    root = mod_etree.XML(self.xml)
           ^^^^^^^^^^^^^^^^^^^^^^^
  File "/usr/local/python/3.12.1/lib/python3.12/xml/etree/ElementTree.py", line 1324, in XML
    return parser.close()
           ^^^^^^^^^^^^^^
xml.etree.ElementTree.ParseError: no element found: line 1, column 0

The above exception was the direct cause of the following exception:

Traceback (most recent call last):
  File "/usr/local/python/3.12.1/lib/python3.12/site-packages/django/core/handlers/exception.py", line 55, in inner
    response = get_response(request)
               ^^^^^^^^^^^^^^^^^^^^^
  File "/usr/local/python/3.12.1/lib/python3.12/site-packages/django/core/handlers/base.py", line 197, in _get_response
    response = wrapped_callback(request, *callback_args, **callback_kwargs)
               ^^^^^^^^^^^^^^^^^^^^^^^^^^^^^^^^^^^^^^^^^^^^^^^^^^^^^^^^^^^^
  File "/usr/local/python/3.12.1/lib/python3.12/site-packages/django/contrib/auth/decorators.py", line 23, in _wrapper_view
    return view_func(request, *args, **kwargs)
           ^^^^^^^^^^^^^^^^^^^^^^^^^^^^^^^^^^^
  File "/workspaces/activitytracker/activitytracker/views.py", line 140, in record_activity
    parsed_data = parse_gpx_file(uploaded_file)
                  ^^^^^^^^^^^^^^^^^^^^^^^^^^^^^
  File "/workspaces/activitytracker/activitytracker/forms.py", line 121, in parse_gpx_file
    gpx = gpxpy.parse(uploaded_file.read())
          ^^^^^^^^^^^^^^^^^^^^^^^^^^^^^^^^^
  File "/usr/local/python/3.12.1/lib/python3.12/site-packages/gpxpy/__init__.py", line 39, in parse
    return parser.parse(version)
           ^^^^^^^^^^^^^^^^^^^^^
  File "/usr/local/python/3.12.1/lib/python3.12/site-packages/gpxpy/parser.py", line 146, in parse
    raise mod_gpx.GPXXMLSyntaxException(f'Error parsing XML: {e}', e)
gpxpy.gpx.GPXXMLSyntaxException: Error parsing XML: no element found: line 1, column 0
"POST /api/activitytracker/record/ HTTP/1.1" 500 106888
Not Found: /favicon.ico
"GET /favicon.ico HTTP/1.1" 404 3348
/workspaces/activitytracker/activitytracker/forms.py changed, reloading.
Watching for file changes with StatReloader
/workspaces/activitytracker/activitytracker/forms.py changed, reloading.
Watching for file changes with StatReloader
Watching for file changes with StatReloader
"GET / HTTP/1.1" 200 3168
"GET /api/activitytracker/dashboard/ HTTP/1.1" 200 13805
Internal Server Error: /api/activitytracker/record/
Traceback (most recent call last):
  File "/usr/local/python/3.12.1/lib/python3.12/site-packages/gpxpy/parser.py", line 134, in parse
    root = mod_etree.XML(self.xml)
           ^^^^^^^^^^^^^^^^^^^^^^^
  File "/usr/local/python/3.12.1/lib/python3.12/xml/etree/ElementTree.py", line 1324, in XML
    return parser.close()
           ^^^^^^^^^^^^^^
xml.etree.ElementTree.ParseError: no element found: line 1, column 0

The above exception was the direct cause of the following exception:

Traceback (most recent call last):
  File "/usr/local/python/3.12.1/lib/python3.12/site-packages/django/core/handlers/exception.py", line 55, in inner
    response = get_response(request)
               ^^^^^^^^^^^^^^^^^^^^^
  File "/usr/local/python/3.12.1/lib/python3.12/site-packages/django/core/handlers/base.py", line 197, in _get_response
    response = wrapped_callback(request, *callback_args, **callback_kwargs)
               ^^^^^^^^^^^^^^^^^^^^^^^^^^^^^^^^^^^^^^^^^^^^^^^^^^^^^^^^^^^^
  File "/usr/local/python/3.12.1/lib/python3.12/site-packages/django/contrib/auth/decorators.py", line 23, in _wrapper_view
    return view_func(request, *args, **kwargs)
           ^^^^^^^^^^^^^^^^^^^^^^^^^^^^^^^^^^^
  File "/workspaces/activitytracker/activitytracker/views.py", line 125, in record_activity
    if form.is_valid():
       ^^^^^^^^^^^^^^^
  File "/usr/local/python/3.12.1/lib/python3.12/site-packages/django/forms/forms.py", line 197, in is_valid
    return self.is_bound and not self.errors
                                 ^^^^^^^^^^^
  File "/usr/local/python/3.12.1/lib/python3.12/site-packages/django/forms/forms.py", line 192, in errors
    self.full_clean()
  File "/usr/local/python/3.12.1/lib/python3.12/site-packages/django/forms/forms.py", line 327, in full_clean
    self._clean_fields()
  File "/usr/local/python/3.12.1/lib/python3.12/site-packages/django/forms/forms.py", line 342, in _clean_fields
    value = getattr(self, "clean_%s" % name)()
            ^^^^^^^^^^^^^^^^^^^^^^^^^^^^^^^^^^
  File "/workspaces/activitytracker/activitytracker/forms.py", line 111, in clean_file
    parsed_data = parse_gpx_file(uploaded_file)
                  ^^^^^^^^^^^^^^^^^^^^^^^^^^^^^
  File "/workspaces/activitytracker/activitytracker/forms.py", line 124, in parse_gpx_file
    gpx = gpxpy.parse(uploaded_file.read())
          ^^^^^^^^^^^^^^^^^^^^^^^^^^^^^^^^^
  File "/usr/local/python/3.12.1/lib/python3.12/site-packages/gpxpy/__init__.py", line 39, in parse
    return parser.parse(version)
           ^^^^^^^^^^^^^^^^^^^^^
  File "/usr/local/python/3.12.1/lib/python3.12/site-packages/gpxpy/parser.py", line 146, in parse
    raise mod_gpx.GPXXMLSyntaxException(f'Error parsing XML: {e}', e)
gpxpy.gpx.GPXXMLSyntaxException: Error parsing XML: no element found: line 1, column 0
"POST /api/activitytracker/record/ HTTP/1.1" 500 133633
"GET / HTTP/1.1" 200 3168
"GET /api/activitytracker/dashboard/ HTTP/1.1" 200 13805
Internal Server Error: /api/activitytracker/record/
Traceback (most recent call last):
  File "/usr/local/python/3.12.1/lib/python3.12/site-packages/django/core/handlers/exception.py", line 55, in inner
    response = get_response(request)
               ^^^^^^^^^^^^^^^^^^^^^
  File "/usr/local/python/3.12.1/lib/python3.12/site-packages/django/core/handlers/base.py", line 197, in _get_response
    response = wrapped_callback(request, *callback_args, **callback_kwargs)
               ^^^^^^^^^^^^^^^^^^^^^^^^^^^^^^^^^^^^^^^^^^^^^^^^^^^^^^^^^^^^
  File "/usr/local/python/3.12.1/lib/python3.12/site-packages/django/contrib/auth/decorators.py", line 23, in _wrapper_view
    return view_func(request, *args, **kwargs)
           ^^^^^^^^^^^^^^^^^^^^^^^^^^^^^^^^^^^
  File "/workspaces/activitytracker/activitytracker/views.py", line 125, in record_activity
    if form.is_valid():
       ^^^^^^^^^^^^^^^
  File "/usr/local/python/3.12.1/lib/python3.12/site-packages/django/forms/forms.py", line 197, in is_valid
    return self.is_bound and not self.errors
                                 ^^^^^^^^^^^
  File "/usr/local/python/3.12.1/lib/python3.12/site-packages/django/forms/forms.py", line 192, in errors
    self.full_clean()
  File "/usr/local/python/3.12.1/lib/python3.12/site-packages/django/forms/forms.py", line 327, in full_clean
    self._clean_fields()
  File "/usr/local/python/3.12.1/lib/python3.12/site-packages/django/forms/forms.py", line 342, in _clean_fields
    value = getattr(self, "clean_%s" % name)()
            ^^^^^^^^^^^^^^^^^^^^^^^^^^^^^^^^^^
  File "/workspaces/activitytracker/activitytracker/forms.py", line 100, in clean_file
    file_content = uploaded_file.read().decode('utf-8')
                   ^^^^^^^^^^^^^^^^^^^^^^^^^^^^^^^^^^^^
UnicodeDecodeError: 'utf-8' codec can't decode byte 0xa6 in position 5: invalid start byte
"POST /api/activitytracker/record/ HTTP/1.1" 500 111457
/workspaces/activitytracker/activitytracker/forms.py changed, reloading.
Watching for file changes with StatReloader
"POST /api/activitytracker/record/ HTTP/1.1" 200 6762
"GET /static/activitytracker/images/trackerlogo.jpg HTTP/1.1" 200 196085
"GET /static/activitytracker/images/backgroundimage.jpg HTTP/1.1" 200 6235780
"POST /api/activitytracker/record/ HTTP/1.1" 200 6762
"GET /static/activitytracker/images/trackerlogo.jpg HTTP/1.1" 200 196085
"GET /static/activitytracker/images/backgroundimage.jpg HTTP/1.1" 200 6235780
"GET /static/activitytracker/images/favicon.ico HTTP/1.1" 200 15406
"POST /api/activitytracker/record/ HTTP/1.1" 200 6762
"GET / HTTP/1.1" 200 3168
"GET /api/activitytracker/dashboard/ HTTP/1.1" 200 13805
"POST /api/activitytracker/record/ HTTP/1.1" 200 6762
/workspaces/activitytracker/activitytracker/forms.py changed, reloading.
Watching for file changes with StatReloader
"GET / HTTP/1.1" 200 3168
"GET /api/activitytracker/dashboard/ HTTP/1.1" 200 13805
"POST /api/activitytracker/record/ HTTP/1.1" 302 0
"GET /api/activitytracker/dashboard/ HTTP/1.1" 200 14267
"GET /api/activitytracker/update/38/ HTTP/1.1" 200 5398
"POST /api/activitytracker/update/38/ HTTP/1.1" 302 0
"GET /api/activitytracker/list/ HTTP/1.1" 200 14267
"GET /api/activitytracker/update/38/ HTTP/1.1" 200 5398
/workspaces/activitytracker/activitytracker/models.py changed, reloading.
Watching for file changes with StatReloader
"GET / HTTP/1.1" 200 3168
"GET /api/activitytracker/dashboard/ HTTP/1.1" 200 14253
"GET /api/activitytracker/dashboard/ HTTP/1.1" 200 14246
"GET /static/activitytracker/images/trackerlogo.jpg HTTP/1.1" 200 196085
"GET /static/activitytracker/images/backgroundimage.jpg HTTP/1.1" 200 6235780
"GET /static/activitytracker/images/favicon.ico HTTP/1.1" 200 15406
/workspaces/activitytracker/activitytracker/urls.py changed, reloading.
Watching for file changes with StatReloader
Unauthorized: /api/activitytracker/api/activities/
/workspaces/activitytracker/activitytracker/views.py changed, reloading.
Watching for file changes with StatReloader
Unauthorized: /api/activitytracker/api/activities/
Unauthorized: /api/activitytracker/api/activities/
"GET / HTTP/1.1" 200 3168
"GET /api/activitytracker/accounts/profile/ HTTP/1.1" 200 4605
"GET /static/css/register.css HTTP/1.1" 200 523
Unauthorized: /api/activitytracker/api/activities/
Unauthorized: /api/activitytracker/api/activities/
Unauthorized: /api/activitytracker/api/activities/
Unauthorized: /api/activitytracker/api/activities/
Unauthorized: /api/activitytracker/api/activities/
Unauthorized: /api/activitytracker/api/activities/
Unauthorized: /api/activitytracker/api/activities/
Unauthorized: /api/activitytracker/api/activities/
Unauthorized: /api/activitytracker/api/activities/
Unauthorized: /api/activitytracker/api/activities/
Unauthorized: /api/activitytracker/api/activities/
Watching for file changes with StatReloader
Unauthorized: /api/activitytracker/api/activities/
/workspaces/activitytracker/activitytracker/urls.py changed, reloading.
Watching for file changes with StatReloader
Unauthorized: /api/activitytracker/api/activities/
Unauthorized: /api/activitytracker/api/activities/
/workspaces/activitytracker/activitytracker/views.py changed, reloading.
Watching for file changes with StatReloader
Bad Request: /api/activitytracker/record/
Unauthorized: /api/activitytracker/api/activities/
/workspaces/activitytracker/activitytracker/views.py changed, reloading.
Watching for file changes with StatReloader
/workspaces/activitytracker/activitytracker/views.py changed, reloading.
Watching for file changes with StatReloader
/workspaces/activitytracker/activitytracker/views.py changed, reloading.
Watching for file changes with StatReloader
/workspaces/activitytracker/activitytracker/views.py changed, reloading.
Watching for file changes with StatReloader
Internal Server Error: /api/activitytracker/record/
Traceback (most recent call last):
  File "/usr/local/python/3.12.1/lib/python3.12/site-packages/django/core/handlers/exception.py", line 55, in inner
    response = get_response(request)
               ^^^^^^^^^^^^^^^^^^^^^
  File "/usr/local/python/3.12.1/lib/python3.12/site-packages/django/core/handlers/base.py", line 197, in _get_response
    response = wrapped_callback(request, *callback_args, **callback_kwargs)
               ^^^^^^^^^^^^^^^^^^^^^^^^^^^^^^^^^^^^^^^^^^^^^^^^^^^^^^^^^^^^
  File "/usr/local/python/3.12.1/lib/python3.12/site-packages/django/views/decorators/csrf.py", line 65, in _view_wrapper
    return view_func(request, *args, **kwargs)
           ^^^^^^^^^^^^^^^^^^^^^^^^^^^^^^^^^^^
  File "/usr/local/python/3.12.1/lib/python3.12/site-packages/django/views/generic/base.py", line 104, in view
    return self.dispatch(request, *args, **kwargs)
           ^^^^^^^^^^^^^^^^^^^^^^^^^^^^^^^^^^^^^^^
  File "/usr/local/python/3.12.1/lib/python3.12/site-packages/rest_framework/views.py", line 509, in dispatch
    response = self.handle_exception(exc)
               ^^^^^^^^^^^^^^^^^^^^^^^^^^
  File "/usr/local/python/3.12.1/lib/python3.12/site-packages/rest_framework/views.py", line 469, in handle_exception
    self.raise_uncaught_exception(exc)
  File "/usr/local/python/3.12.1/lib/python3.12/site-packages/rest_framework/views.py", line 480, in raise_uncaught_exception
    raise exc
  File "/usr/local/python/3.12.1/lib/python3.12/site-packages/rest_framework/views.py", line 506, in dispatch
    response = handler(request, *args, **kwargs)
               ^^^^^^^^^^^^^^^^^^^^^^^^^^^^^^^^^
  File "/usr/local/python/3.12.1/lib/python3.12/site-packages/rest_framework/decorators.py", line 50, in handler
    return func(*args, **kwargs)
           ^^^^^^^^^^^^^^^^^^^^^
  File "/workspaces/activitytracker/activitytracker/views.py", line 105, in record_activity
    if form.is_valid():
       ^^^^^^^^^^^^^^^
  File "/usr/local/python/3.12.1/lib/python3.12/site-packages/django/forms/forms.py", line 197, in is_valid
    return self.is_bound and not self.errors
                                 ^^^^^^^^^^^
  File "/usr/local/python/3.12.1/lib/python3.12/site-packages/django/forms/forms.py", line 192, in errors
    self.full_clean()
  File "/usr/local/python/3.12.1/lib/python3.12/site-packages/django/forms/forms.py", line 327, in full_clean
    self._clean_fields()
  File "/usr/local/python/3.12.1/lib/python3.12/site-packages/django/forms/forms.py", line 342, in _clean_fields
    value = getattr(self, "clean_%s" % name)()
            ^^^^^^^^^^^^^^^^^^^^^^^^^^^^^^^^^^
  File "/workspaces/activitytracker/activitytracker/forms.py", line 79, in clean_duration
    parts = duration.split(':')
            ^^^^^^^^^^^^^^
AttributeError: 'datetime.timedelta' object has no attribute 'split'
Unauthorized: /api/activitytracker/api/activities/
/workspaces/activitytracker/activitytracker/forms.py changed, reloading.
Watching for file changes with StatReloader
Watching for file changes with StatReloader
/workspaces/activitytracker/activitytracker/forms.py changed, reloading.
Watching for file changes with StatReloader
Watching for file changes with StatReloader
Unauthorized: /api/activitytracker/api/activities/
/workspaces/activitytracker/activitytracker/views.py changed, reloading.
Watching for file changes with StatReloader
/workspaces/activitytracker/activitytracker/urls.py changed, reloading.
Watching for file changes with StatReloader
/workspaces/activitytracker/tracker/settings.py changed, reloading.
Watching for file changes with StatReloader
Unauthorized: /api/token/
"POST /api/token/ HTTP/1.1" 401 63
/workspaces/activitytracker/activitytracker/urls.py changed, reloading.
Watching for file changes with StatReloader
Watching for file changes with StatReloader
Unauthorized: /api/token/
"POST /api/token/ HTTP/1.1" 401 63
Watching for file changes with StatReloader
Unauthorized: /api/token/
"POST /api/token/ HTTP/1.1" 401 63
"POST /api/token/ HTTP/1.1" 200 486
Not Found: /your-protected-endpoint/
"GET /your-protected-endpoint/ HTTP/1.1" 404 3387
Unauthorized: /api/activitytracker/activity-log/
Unauthorized: /api/activitytracker/api/activities/
Unauthorized: /api/activitytracker/api/register/
Bad Request: /api/activitytracker/api/activities/
Unauthorized: /api/activitytracker/api/register/
/workspaces/activitytracker/activitytracker/views.py changed, reloading.
Watching for file changes with StatReloader
/workspaces/activitytracker/activitytracker/views.py changed, reloading.
Watching for file changes with StatReloader
Bad Request: /api/activitytracker/api/activities/
Watching for file changes with StatReloader
